Workbook

Sheet 說明
A1: 中信 VCF 9.1.1 Converge & Import — 每一步 Checklist
A2: 版本 v1｜2026-10-07｜Broadcom CXS｜對應簡報：CTBC_VCF911_Converge_Import_Plan.pptx
A4: 範圍 | B4: Management Cluster Converge → VCF 9.1.1 管理網域；vRA 8.18 → VCF Automation 9.1.1；整合雲 / 中信雲 Import 為 VI Workload Domain 並升級 9.1.1；SRM 重新註冊；vRO → 9.1.1。不含 NSX Edge cluster。
A5: 路徑假設 | B5: WLD 採方案 B：vCenter 先以 RDU 升 9.1.1 → SRM Reconfigure → Import（共用管理網域 NSX 9.1.1）→ ESXi 走 VCF LCM。若改方案 A，S07–S14 需改寫（見簡報 Decision 頁）。
A6: 已確認事項 | B6: 2026-10-07：三套 vCenter 皆無 Enhanced Linked Mode（客戶確認）。
A7: 怎麼填 | B7: 只需填黃底欄位：『Checklist』頁的 狀態 / 執行人 / 完成時間 / 證據 / 備註；『Gate 簽核』、『IP & DNS 規劃』、『待確認事項』的黃底欄。其餘為計畫內容，請勿改動。
A8: 填寫範例 | B8: 狀態＝完成｜執行人＝王小明（中信 系統）｜完成時間＝2026-10-19 14:30｜證據＝S04-12_converge-success.png｜備註＝Validation 2 個 Warning 已確認
A9: 狀態選項 | B9: 未開始 / 進行中 / 完成 / 失敗 / N/A（下拉選單；『進度總覽』頁自動統計）
A10: 類別 | B10: 前置檢查 → 執行 → 完成驗證 → 退版 / 截止點。每一步的『退版』列須在 Lab 演練過才可進正式環境。
A11: 依據欄 | B11: TechDocs / KB = Broadcom 官方文件；CXS Lab 實測 = Broadcom CXS 內部 lab 實測結果（非官方文件）；推定 = 目前無官方文件直接說明，需 Lab 驗證或開 SR 確認。
A12: 帳密原則 | B12: 本表不記錄任何帳號密碼；需要密碼的步驟一律由客戶密碼保管工具提供。
A13: 負責代號 | B13: PM 專案經理、ARC 架構師、ENG 升級工程師、SYS 系統、HW 硬體、NET 網路、SEC 資安、DR DR 負責人、AUTO 自動化平台、APP 應用驗證、CHG 變更管理、GSS 原廠支援（同人員表）
A15: Gate 與 PONR
A16: Gate | B16: 時點 / 說明
A17: G0 | B17: S00 後｜盤點與備份｜放行條件：阻礙項清零、三套 vCenter 備份可還原、IP/DNS 驗證完成｜簽核：PM、ARC
A18: G1 ⚠ PONR | B18: S04 後｜Converge 完成｜放行條件：管理網域 ACTIVE、NSX / VCF Ops 正常、第一次 SFTP 備份成功｜簽核：PM、ARC
A19: G2 | B19: S06 後｜VCFA 9.1.1 cutover｜放行條件：Tenant / Provider 登入、資料完整、Day-2 成功；8.18 來源保留至觀察期後｜簽核：PM、AUTO
A20: G3 ⚠ PONR | B20: S09｜整合雲 import｜放行條件：vCenter 9.1.1 正常、SRM Test Recovery 成功、Compute Manager 已註冊｜簽核：PM、ARC、DR
A21: G4 ⚠ PONR | B21: S13｜中信雲 import｜放行條件：同 G3｜簽核：PM、ARC、DR
A22: G5 ⚠ PONR | B22: S16｜vSAN on-disk format｜放行條件：觀察期無重大事件、客戶簽核｜簽核：PM

Sheet 進度總覽
A1: 進度總覽（自動統計自『Checklist』頁，請勿手改）
A3: Step | B3: 步驟 | C3: 階段 | D3: Gate | E3: 項目數 | F3: 完成 | G3: N/A | H3: 失敗 | I3: 進行中 | J3: 完成率
A4: S00 | B4: 盤點、阻礙項排除與備份（新增） | C4: 準備 | D4: G0 | E4: =COUNTIFS(Checklist!$A$4:$A$201,$A4,Checklist!$D$4:$D$201,"<>步驟") -> 15 | F4: =COUNTIFS(Checklist!$A$4:$A$201,$A4,Checklist!$K$4:$K$201,"完成") -> 0 | G4: =COUNTIFS(Checklist!$A$4:$A$201,$A4,Checklist!$K$4:$K$201,"N/A") -> 0 | H4: =COUNTIFS(Checklist!$A$4:$A$201,$A4,Checklist!$K$4:$K$201,"失敗") -> 0 | I4: =COUNTIFS(Checklist!$A$4:$A$201,$A4,Checklist!$K$4:$K$201,"進行中") -> 0 | J4: =IF(E4=0,0,(F4+G4)/E4) -> 0
A5: S01 | B5: vRA / vRO 冷遷移至 Management Cluster（#1） | C5: 管理網域 | E5: =COUNTIFS(Checklist!$A$4:$A$201,$A5,Checklist!$D$4:$D$201,"<>步驟") -> 15 | F5: =COUNTIFS(Checklist!$A$4:$A$201,$A5,Checklist!$K$4:$K$201,"完成") -> 0 | G5: =COUNTIFS(Checklist!$A$4:$A$201,$A5,Checklist!$K$4:$K$201,"N/A") -> 0 | H5: =COUNTIFS(Checklist!$A$4:$A$201,$A5,Checklist!$K$4:$K$201,"失敗") -> 0 | I5: =COUNTIFS(Checklist!$A$4:$A$201,$A5,Checklist!$K$4:$K$201,"進行中") -> 0 | J5: =IF(E5=0,0,(F5+G5)/E5) -> 0
A6: S02 | B6: 部署 VCF Installer 9.1.1（#3） | C6: 管理網域 | E6: =COUNTIFS(Checklist!$A$4:$A$201,$A6,Checklist!$D$4:$D$201,"<>步驟") -> 6 | F6: =COUNTIFS(Checklist!$A$4:$A$201,$A6,Checklist!$K$4:$K$201,"完成") -> 0 | G6: =COUNTIFS(Checklist!$A$4:$A$201,$A6,Checklist!$K$4:$K$201,"N/A") -> 0 | H6: =COUNTIFS(Checklist!$A$4:$A$201,$A6,Checklist!$K$4:$K$201,"失敗") -> 0 | I6: =COUNTIFS(Checklist!$A$4:$A$201,$A6,Checklist!$K$4:$K$201,"進行中") -> 0 | J6: =IF(E6=0,0,(F6+G6)/E6) -> 0
A7: S03 | B7: Depot 與 Binaries（回答「Offline Depot???」）（#4） | C7: 管理網域 | E7: =COUNTIFS(Checklist!$A$4:$A$201,$A7,Checklist!$D$4:$D$201,"<>步驟") -> 12 | F7: =COUNTIFS(Checklist!$A$4:$A$201,$A7,Checklist!$K$4:$K$201,"完成") -> 0 | G7: =COUNTIFS(Checklist!$A$4:$A$201,$A7,Checklist!$K$4:$K$201,"N/A") -> 0 | H7: =COUNTIFS(Checklist!$A$4:$A$201,$A7,Checklist!$K$4:$K$201,"失敗") -> 0 | I7: =COUNTIFS(Checklist!$A$4:$A$201,$A7,Checklist!$K$4:$K$201,"進行中") -> 0 | J7: =IF(E7=0,0,(F7+G7)/E7) -> 0
A8: S04 | B8: Management Cluster Converge 成 VCF 9.1.1 管理網域（#5） | C8: 管理網域 | D8: G1 ⚠ PONR | E8: =COUNTIFS(Checklist!$A$4:$A$201,$A8,Checklist!$D$4:$D$201,"<>步驟") -> 16 | F8: =COUNTIFS(Checklist!$A$4:$A$201,$A8,Checklist!$K$4:$K$201,"完成") -> 0 | G8: =COUNTIFS(Checklist!$A$4:$A$201,$A8,Checklist!$K$4:$K$201,"N/A") -> 0 | H8: =COUNTIFS(Checklist!$A$4:$A$201,$A8,Checklist!$K$4:$K$201,"失敗") -> 0 | I8: =COUNTIFS(Checklist!$A$4:$A$201,$A8,Checklist!$K$4:$K$201,"進行中") -> 0 | J8: =IF(E8=0,0,(F8+G8)/E8) -> 0
A9: S05 | B9: vRA 匯入 VCF Operations（Fleet Lifecycle）（#6） | C9: 管理網域 | E9: =COUNTIFS(Checklist!$A$4:$A$201,$A9,Checklist!$D$4:$D$201,"<>步驟") -> 8 | F9: =COUNTIFS(Checklist!$A$4:$A$201,$A9,Checklist!$K$4:$K$201,"完成") -> 0 | G9: =COUNTIFS(Checklist!$A$4:$A$201,$A9,Checklist!$K$4:$K$201,"N/A") -> 0 | H9: =COUNTIFS(Checklist!$A$4:$A$201,$A9,Checklist!$K$4:$K$201,"失敗") -> 0 | I9: =COUNTIFS(Checklist!$A$4:$A$201,$A9,Checklist!$K$4:$K$201,"進行中") -> 0 | J9: =IF(E9=0,0,(F9+G9)/E9) -> 0
A10: S06 | B10: vRA 8.18 → VCF Automation 9.1.1（藍綠升級）（#7） | C10: 管理網域 | D10: G2 | E10: =COUNTIFS(Checklist!$A$4:$A$201,$A10,Checklist!$D$4:$D$201,"<>步驟") -> 19 | F10: =COUNTIFS(Checklist!$A$4:$A$201,$A10,Checklist!$K$4:$K$201,"完成") -> 0 | G10: =COUNTIFS(Checklist!$A$4:$A$201,$A10,Checklist!$K$4:$K$201,"N/A") -> 0 | H10: =COUNTIFS(Checklist!$A$4:$A$201,$A10,Checklist!$K$4:$K$201,"失敗") -> 0 | I10: =COUNTIFS(Checklist!$A$4:$A$201,$A10,Checklist!$K$4:$K$201,"進行中") -> 0 | J10: =IF(E10=0,0,(F10+G10)/E10) -> 0
A11: S07 | B11: 整合雲 vCenter 8.0.3 → 9.1.1（RDU，import 前）（#10（vCenter）） | C11: 整合雲 | E11: =COUNTIFS(Checklist!$A$4:$A$201,$A11,Checklist!$D$4:$D$201,"<>步驟") -> 12 | F11: =COUNTIFS(Checklist!$A$4:$A$201,$A11,Checklist!$K$4:$K$201,"完成") -> 0 | G11: =COUNTIFS(Checklist!$A$4:$A$201,$A11,Checklist!$K$4:$K$201,"N/A") -> 0 | H11: =COUNTIFS(Checklist!$A$4:$A$201,$A11,Checklist!$K$4:$K$201,"失敗") -> 0 | I11: =COUNTIFS(Checklist!$A$4:$A$201,$A11,Checklist!$K$4:$K$201,"進行中") -> 0 | J11: =IF(E11=0,0,(F11+G11)/E11) -> 0
A12: S08 | B12: 整合雲 vCenter 升級後 SRM 重新註冊（#11） | C12: 整合雲 | E12: =COUNTIFS(Checklist!$A$4:$A$201,$A12,Checklist!$D$4:$D$201,"<>步驟") -> 8 | F12: =COUNTIFS(Checklist!$A$4:$A$201,$A12,Checklist!$K$4:$K$201,"完成") -> 0 | G12: =COUNTIFS(Checklist!$A$4:$A$201,$A12,Checklist!$K$4:$K$201,"N/A") -> 0 | H12: =COUNTIFS(Checklist!$A$4:$A$201,$A12,Checklist!$K$4:$K$201,"失敗") -> 0 | I12: =COUNTIFS(Checklist!$A$4:$A$201,$A12,Checklist!$K$4:$K$201,"進行中") -> 0 | J12: =IF(E12=0,0,(F12+G12)/E12) -> 0
A13: S09 | B13: 整合雲 匯入為 VI Workload Domain（共用管理網域 NSX 9.1.1）（#8） | C13: 整合雲 | D13: G3 ⚠ PONR | E13: =COUNTIFS(Checklist!$A$4:$A$201,$A13,Checklist!$D$4:$D$201,"<>步驟") -> 9 | F13: =COUNTIFS(Checklist!$A$4:$A$201,$A13,Checklist!$K$4:$K$201,"完成") -> 0 | G13: =COUNTIFS(Checklist!$A$4:$A$201,$A13,Checklist!$K$4:$K$201,"N/A") -> 0 | H13: =COUNTIFS(Checklist!$A$4:$A$201,$A13,Checklist!$K$4:$K$201,"失敗") -> 0 | I13: =COUNTIFS(Checklist!$A$4:$A$201,$A13,Checklist!$K$4:$K$201,"進行中") -> 0 | J13: =IF(E13=0,0,(F13+G13)/E13) -> 0
A14: S10 | B14: 整合雲 ESXi 8.0.3 → 9.1.1（VCF LCM / vLCM image）（#10（ESXi）） | C14: 整合雲 | E14: =COUNTIFS(Checklist!$A$4:$A$201,$A14,Checklist!$D$4:$D$201,"<>步驟") -> 7 | F14: =COUNTIFS(Checklist!$A$4:$A$201,$A14,Checklist!$K$4:$K$201,"完成") -> 0 | G14: =COUNTIFS(Checklist!$A$4:$A$201,$A14,Checklist!$K$4:$K$201,"N/A") -> 0 | H14: =COUNTIFS(Checklist!$A$4:$A$201,$A14,Checklist!$K$4:$K$201,"失敗") -> 0 | I14: =COUNTIFS(Checklist!$A$4:$A$201,$A14,Checklist!$K$4:$K$201,"進行中") -> 0 | J14: =IF(E14=0,0,(F14+G14)/E14) -> 0
A15: S11 | B15: 中信雲 vCenter 8.0.3 → 9.1.1（RDU，import 前）（#12（vCenter）） | C15: 中信雲 | E15: =COUNTIFS(Checklist!$A$4:$A$201,$A15,Checklist!$D$4:$D$201,"<>步驟") -> 14 | F15: =COUNTIFS(Checklist!$A$4:$A$201,$A15,Checklist!$K$4:$K$201,"完成") -> 0 | G15: =COUNTIFS(Checklist!$A$4:$A$201,$A15,Checklist!$K$4:$K$201,"N/A") -> 0 | H15: =COUNTIFS(Checklist!$A$4:$A$201,$A15,Checklist!$K$4:$K$201,"失敗") -> 0 | I15: =COUNTIFS(Checklist!$A$4:$A$201,$A15,Checklist!$K$4:$K$201,"進行中") -> 0 | J15: =IF(E15=0,0,(F15+G15)/E15) -> 0
A16: S12 | B16: 中信雲 vCenter 升級後 SRM 重新註冊（#13） | C16: 中信雲 | E16: =COUNTIFS(Checklist!$A$4:$A$201,$A16,Checklist!$D$4:$D$201,"<>步驟") -> 9 | F16: =COUNTIFS(Checklist!$A$4:$A$201,$A16,Checklist!$K$4:$K$201,"完成") -> 0 | G16: =COUNTIFS(Checklist!$A$4:$A$201,$A16,Checklist!$K$4:$K$201,"N/A") -> 0 | H16: =COUNTIFS(Checklist!$A$4:$A$201,$A16,Checklist!$K$4:$K$201,"失敗") -> 0 | I16: =COUNTIFS(Checklist!$A$4:$A$201,$A16,Checklist!$K$4:$K$201,"進行中") -> 0 | J16: =IF(E16=0,0,(F16+G16)/E16) -> 0
A17: S13 | B17: 中信雲 匯入為 VI Workload Domain（共用管理網域 NSX 9.1.1）（#9） | C17: 中信雲 | D17: G4 ⚠ PONR | E17: =COUNTIFS(Checklist!$A$4:$A$201,$A17,Checklist!$D$4:$D$201,"<>步驟") -> 9 | F17: =COUNTIFS(Checklist!$A$4:$A$201,$A17,Checklist!$K$4:$K$201,"完成") -> 0 | G17: =COUNTIFS(Checklist!$A$4:$A$201,$A17,Checklist!$K$4:$K$201,"N/A") -> 0 | H17: =COUNTIFS(Checklist!$A$4:$A$201,$A17,Checklist!$K$4:$K$201,"失敗") -> 0 | I17: =COUNTIFS(Checklist!$A$4:$A$201,$A17,Checklist!$K$4:$K$201,"進行中") -> 0 | J17: =IF(E17=0,0,(F17+G17)/E17) -> 0
A18: S14 | B18: 中信雲 ESXi 8.0.3 → 9.1.1（VCF LCM / vLCM image）（#12（ESXi）） | C18: 中信雲 | E18: =COUNTIFS(Checklist!$A$4:$A$201,$A18,Checklist!$D$4:$D$201,"<>步驟") -> 7 | F18: =COUNTIFS(Checklist!$A$4:$A$201,$A18,Checklist!$K$4:$K$201,"完成") -> 0 | G18: =COUNTIFS(Checklist!$A$4:$A$201,$A18,Checklist!$K$4:$K$201,"N/A") -> 0 | H18: =COUNTIFS(Checklist!$A$4:$A$201,$A18,Checklist!$K$4:$K$201,"失敗") -> 0 | I18: =COUNTIFS(Checklist!$A$4:$A$201,$A18,Checklist!$K$4:$K$201,"進行中") -> 0 | J18: =IF(E18=0,0,(F18+G18)/E18) -> 0
A19: S15 | B19: vRO → VCF Operations orchestrator 9.1.1（VCFA 之後）（#2（移到最後）） | C19: 收尾 | E19: =COUNTIFS(Checklist!$A$4:$A$201,$A19,Checklist!$D$4:$D$201,"<>步驟") -> 9 | F19: =COUNTIFS(Checklist!$A$4:$A$201,$A19,Checklist!$K$4:$K$201,"完成") -> 0 | G19: =COUNTIFS(Checklist!$A$4:$A$201,$A19,Checklist!$K$4:$K$201,"N/A") -> 0 | H19: =COUNTIFS(Checklist!$A$4:$A$201,$A19,Checklist!$K$4:$K$201,"失敗") -> 0 | I19: =COUNTIFS(Checklist!$A$4:$A$201,$A19,Checklist!$K$4:$K$201,"進行中") -> 0 | J19: =IF(E19=0,0,(F19+G19)/E19) -> 0
A20: S16 | B20: 觀察期、vSAN on-disk format 與收尾（新增） | C20: 收尾 | D20: G5 ⚠ PONR | E20: =COUNTIFS(Checklist!$A$4:$A$201,$A20,Checklist!$D$4:$D$201,"<>步驟") -> 6 | F20: =COUNTIFS(Checklist!$A$4:$A$201,$A20,Checklist!$K$4:$K$201,"完成") -> 0 | G20: =COUNTIFS(Checklist!$A$4:$A$201,$A20,Checklist!$K$4:$K$201,"N/A") -> 0 | H20: =COUNTIFS(Checklist!$A$4:$A$201,$A20,Checklist!$K$4:$K$201,"失敗") -> 0 | I20: =COUNTIFS(Checklist!$A$4:$A$201,$A20,Checklist!$K$4:$K$201,"進行中") -> 0 | J20: =IF(E20=0,0,(F20+G20)/E20) -> 0
A21: 合計 | E21: =SUM(E4:E20) -> 181 | F21: =SUM(F4:F20) -> 0 | G21: =SUM(G4:G20) -> 0 | H21: =SUM(H4:H20) -> 0 | I21: =SUM(I4:I20) -> 0 | J21: =IF(E21=0,0,(F21+G21)/E21) -> 0
A23: 完成率 =（完成 + N/A）÷ 項目數；『失敗』不算完成，須依該步『退版』列處理後重做。

Sheet Checklist
A1: 每一步 Checklist（方案 B）
A2: 黃底欄位由執行人填寫；狀態請用下拉選單
A3: Step | B3: 原計畫 | C3: 階段 | D3: 類別 | E3: # | F3: 檢查項目 | G3: 指令 / UI 路徑 | H3: 預期結果 | I3: 依據 | J3: 負責 | K3: 狀態 | L3: 執行人 | M3: 完成時間 | N3: 證據 / 截圖 | O3: 備註
A4: S00 | B4: 新增 | C4: 準備 | D4: 步驟 | F4: S00｜Inventory, Blockers & Backups｜盤點、阻礙項排除與備份｜G0 Gate｜負責：ARC、ENG、SYS、NET、DR、AUTO
A5: S00 | B5: 新增 | C5: 準備 | D5: 前置檢查 | E5: S00-01 | F5: vRA 確切版本 ≥ 8.18.1（converge 情境頁要求 8.18.1 Patch 3，建議以 P3 為基準） | G5: vRA 主節點：vracli version | H5: ≥ 8.18.1 P3 | I5: TechDocs: Import an Existing VMware Aria Automation Instance；Converge … Aria Automation 情境頁 | J5: AUTO | K5: 未開始
A6: S00 | B6: 新增 | C6: 準備 | D6: 前置檢查 | E6: S00-02 | F6: vRO 實際版本（「8.18.7」在 Broadcom 查無此 Orchestrator 版號，需現場確認）且 ≥ 8.18.1 | G6: vRO：vracli version | H6: ≥ 8.18.1 | I6: TechDocs: Upgrade to VCF Operations Orchestrator 9.1 | J6: AUTO | K6: 未開始
A7: S00 | B7: 新增 | C7: 準備 | D7: 前置檢查 | E7: S00-03 | F7: vIDM / Aria Suite Lifecycle 的版本與所在叢集（vIDM 升級後仍是 VCFA 9.1 驗證來源，不可刪） | G7: vSphere Client inventory | H7: 已記錄 | I7: TechDocs: Upgrading to VCF Automation 9.1 | J7: AUTO | K7: 未開始
A8: S00 | B8: 新增 | C8: 準備 | D8: 前置檢查 | E8: S00-04 | F8: 整合雲 / 中信雲 vCenter、ESXi 8.0.3 確切 build：8.0U3j 不可升 9.1.0、可升 9.1.1；8.0U3k 須另查 Interop Matrix（back-in-time） | G8: VAMI Summary；esxcli system version get | H8: 目標 9.1.1 可行 | I8: KB 450972；TechDocs: Upgrading to VCF 9.1.x | J8: SYS | K8: 未開始
A9: S00 | B9: 新增 | C9: 準備 | D9: 前置檢查 | E9: S00-05 | F9: 三套 vCenter 皆無 Enhanced Linked Mode（客戶 2026-10-07 已確認）；另確認無 vCenter HA（converge 與 import 都不支援） | G9: vSphere Client > vCenter > Configure > vCenter HA | H9: 無 ELM ✔、無 VCHA | I9: TechDocs: Supported and Not Supported Configurations；Import an Existing vCenter | J9: SYS | K9: 未開始
A10: S00 | B10: 新增 | C10: 準備 | D10: 前置檢查 | E10: S00-06 | F10: 叢集條件：vLCM image-based、DRS Fully Automated、VDS ≥ 8.0、vmk 靜態 IP、單一 vMotion vmk、ESXi 以 FQDN 加入 inventory | G10: Cluster > Updates / DRS；Host > VMkernel adapters | H10: 全部符合 | I10: TechDocs: Supported and Not Supported Configurations；KB 425102 | J10: SYS | K10: 未開始
A11: S00 | B11: 新增 | C11: 準備 | D11: 前置檢查 | E11: S00-07 | F11: DNS 正反解（A/PTR）一致、所有 FQDN 全小寫（大寫 FQDN 會讓 converge 憑證鏈失敗） | G11: nslookup <fqdn> / nslookup <ip> | H11: 正反解一致、小寫 | I11: KB 453612 | J11: NET | K11: 未開始
A12: S00 | B12: 新增 | C12: 準備 | D12: 前置檢查 | E12: S00-08 | F12: IP / DNS 規劃完成（見『IP & DNS 規劃』頁）：VCF Mgmt Services IP pool ≥ 12（198.18.0.0/15 不可與內網重疊）、License Server A+PTR、VCFA 5 IP + runtime FQDN、RDU 暫時 IP ×2 | H12: 規劃表簽核 | I12: KB 440630；TechDocs: Upgrading to VCF Automation 9.1 | J12: NET | K12: 未開始
A13: S00 | B13: 新增 | C13: 準備 | D13: 前置檢查 | E13: S00-09 | F13: 管理叢集容量：單台主機邏輯 CPU ≥ 最大 VM vCPU（Installer 只驗叢集總量）；VCFA 藍綠升級期間資源約平時 2 倍 | H13: 容量足夠 | I13: CXS Lab 實測 | J13: ARC | K13: 未開始
A14: S00 | B14: 新增 | C14: 準備 | D14: 前置檢查 | E14: S00-10 | F14: SRM 拓樸：兩朵雲是否互為配對、各 Protection Group 方向（protected / recovery）、replication 方式；solution account 密碼不過期設定 | G14: SRM UI > Site Pair；Protection Groups | H14: 已記錄 | I14: TechDocs: Order of Upgrading vSphere and Protection and Recovery Components；KB 367383 | J14: DR | K14: 未開始
A15: S00 | B15: 新增 | C15: 準備 | D15: 前置檢查 | E15: S00-11 | F15: Interop Matrix：VCFA 9.1.1 ↔ vCenter 8.0.3（過渡期）、SRM 9.1.1 ↔ vCenter 8.0.3 / 9.1.1、備份軟體與第三方 plugin ↔ vSphere 9.1.1 | G15: interopmatrix.broadcom.com | H15: 全部 Compatible 或已有對策 | I15: Broadcom Interop Matrix | J15: ARC | K15: 未開始
A16: S00 | B16: 新增 | C16: 準備 | D16: 前置檢查 | E16: S00-12 | F16: 備份：三套 vCenter file-based backup 並抽測還原；SRM 設定匯出；SFTP 備份伺服器就緒 | G16: VAMI > Backup | H16: 備份成功、還原驗證通過 | I16: TechDocs: VCF 9.1 Backup and Restore | J16: SYS | K16: 未開始
A17: S00 | B17: 新增 | C17: 準備 | D17: 執行 | E17: S00-13 | F17: 填寫 Planning & Preparation Workbook；開立變更單（每一步的窗口、退版時間、負責人） | H17: 變更單核准 | J17: PM、CHG | K17: 未開始
A18: S00 | B18: 新增 | C18: 準備 | D18: 完成驗證 | E18: S00-14 | F18: G0 簽核：阻礙項清零、備份可還原、IP/DNS 驗證完成 | H18: G0 Go | J18: PM | K18: 未開始
A19: S00 | B19: 新增 | C19: 準備 | D19: 退版 / 截止點 | E19: S00-15 | F19: 無變更（只做盤點與準備） | K19: 未開始
A20: S01 | B20: #1 | C20: 管理網域 | D20: 步驟 | F20: S01｜Cold-migrate vRA / vRO into the Management Cluster｜vRA / vRO 冷遷移至 Management Cluster｜Lab：165 GB 冷遷移約 97 分 / VM（nested）｜負責：ENG、SYS、AUTO、NET
A21: S01 | B21: #1 | C21: 管理網域 | D21: 前置檢查 | E21: S01-01 | F21: Management Cluster 提供與 vRA / vRO 現行『同一 L2 網段』的 port group（IP / FQDN 不變；VCFA 9.1 新節點也必須部署在同網段） | G21: VDS > Port groups | H21: VLAN / subnet 相同 | I21: TechDocs: Upgrading to VCF Automation 9.1（same network）；Import an Existing VMware Aria Automation Instance | J21: NET | K21: 未開始
A22: S01 | B22: #1 | C22: 管理網域 | D22: 前置檢查 | E22: S01-02 | F22: 順序：CXS Lab 驗證的是管理網域建好後再搬（Converge → 搬 vRA → Import）；先搬再 Converge 亦可，但未經 Lab 驗證 | H22: 已決定 | I22: CXS Lab 實測 | J22: ARC | K22: 未開始
A23: S01 | B23: #1 | C23: 管理網域 | D23: 前置檢查 | E23: S01-03 | F23: 熱 vMotion 不採用：vDS 8.0.3 ↔ 9.1 不同版本間 vMotion 不支援；CXS Lab 熱遷移亦因 CPU feature 失敗 → 排停機窗口冷遷移 | H23: 已排窗口 | I23: KB 318582；CXS Lab 實測 | J23: ARC | K23: 未開始
A24: S01 | B24: #1 | C24: 管理網域 | D24: 前置檢查 | E24: S01-04 | F24: 兩端 vCenter 443、ESXi 902（NFC）互通；目的 datastore 容量足夠 | G24: Test-NetConnection / nc -zv | H24: 可連通 | I24: TechDocs: Import or Clone a VM with Advanced Cross vCenter vMotion | J24: NET | K24: 未開始
A25: S01 | B25: #1 | C25: 管理網域 | D25: 前置檢查 | E25: S01-05 | F25: 記錄各節點 vApp properties / OVF 環境（vApp options 遺失會讓 vRA 服務起不來） | G25: VM > Configure > vApp Options（匯出截圖 / OVF） | H25: 已備份 | I25: KB 447218 | J25: ENG | K25: 未開始
A26: S01 | B26: #1 | C26: 管理網域 | D26: 前置檢查 | E26: S01-06 | F26: 健康基準：vracli status、pods 全 Running；凍結 vRA 請求與 vRO 排程工作流程 | G26: kubectl get pods -n prelude | H26: 全 Running | I26: CXS Lab 實測 | J26: AUTO | K26: 未開始
A27: S01 | B27: #1 | C27: 管理網域 | D27: 執行 | E27: S01-07 | F27: vRA 正常停止服務後關機 | G27: 主節點：/opt/scripts/deploy.sh --shutdown → Guest shutdown 各節點 | H27: 所有節點 Powered off | I27: TechDocs: Aria Automation 8.18 Start / Shut down | J27: ENG | K27: 未開始
A28: S01 | B28: #1 | C28: 管理網域 | D28: 執行 | E28: S01-08 | F28: vRO 正常關機；確認各 VM CD/DVD 未掛 datastore ISO | G28: Guest shutdown；Edit Settings > CD/DVD | H28: Powered off、未掛 ISO | I28: CXS Lab 實測 | J28: ENG | K28: 未開始
A29: S01 | B29: #1 | C29: 管理網域 | D29: 執行 | E29: S01-09 | F29: Advanced Cross vCenter vMotion（關機狀態）：選 mgmt cluster / datastore / 同網段 port group；可選 Clone 方式保留來源（來源保持關機）作為退版點 | G29: vSphere Client（目的 vCenter）> Import VMs；或 PowerCLI Move-VM | H29: 遷移成功 | I29: TechDocs: Import or Clone a VM with Advanced Cross vCenter vMotion | J29: ENG | K29: 未開始
A30: S01 | B30: #1 | C30: 管理網域 | D30: 執行 | E30: S01-10 | F30: 依相依性開機（vRO → vRA 全部節點），vRA 主節點啟動服務 | G30: /opt/scripts/deploy.sh | H30: 服務啟動 | I30: TechDocs: Aria Automation 8.18 Start / Shut down | J30: ENG | K30: 未開始
A31: S01 | B31: #1 | C31: 管理網域 | D31: 完成驗證 | E31: S01-11 | F31: IP / FQDN / vApp properties 不變（ovfEnv 存在） | G31: cat /opt/vmware/etc/vami/ovfEnv.xml | H31: 與遷移前一致 | I31: KB 447218 | J31: ENG | K31: 未開始
A32: S01 | B32: #1 | C32: 管理網域 | D32: 完成驗證 | E32: S01-12 | F32: 服務就緒：healthstatus 回 200、pods 全 Running（約 10–20 分） | G32: curl -k https://<vra-fqdn>/vco/api/healthstatus | H32: HTTP 200 | I32: CXS Lab 實測 | J32: ENG | K32: 未開始
A33: S01 | B33: #1 | C33: 管理網域 | D33: 完成驗證 | E33: S01-13 | F33: vIDM 登入、cloud account data collection、既有部署 Day-2（Power off/on）、新 catalog 請求、vRO workflow 測試 | G33: Cloud Assembly / Service Broker / vRO Client | H33: 全部成功 | I33: CXS Lab 實測 | J33: AUTO | K33: 未開始
A34: S01 | B34: #1 | C34: 管理網域 | D34: 退版 / 截止點 | E34: S01-14 | F34: 反向冷遷移回中信雲；或刪除新 VM、開回 Clone 保留的來源 | H34: 回到遷移前狀態 | J34: ENG | K34: 未開始
A35: S01 | B35: #1 | C35: 管理網域 | D35: 退版 / 截止點 | E35: S01-15 | F35: 截止點：S05 Import 之前 | K35: 未開始
A36: S02 | B36: #3 | C36: 管理網域 | D36: 步驟 | F36: S02｜Deploy VCF Installer 9.1.1｜部署 VCF Installer 9.1.1｜負責：ENG
A37: S02 | B37: #3 | C37: 管理網域 | D37: 前置檢查 | E37: S02-01 | F37: Installer 版本 ≥ 9.1.1（converge 文件要求），與 vCenter / ESXi 同為 9.1.1 BOM（Installer build 25713928） | H37: 版本正確 | I37: TechDocs: Deploy Components by Using VCF Installer…；VCF 9.1.1 BOM | J37: ENG | K37: 未開始
A38: S02 | B38: #3 | C38: 管理網域 | D38: 前置檢查 | E38: S02-02 | F38: Installer IP / FQDN（A/PTR）、NTP、DNS 就緒 | G38: nslookup | H38: 正反解正確 | J38: NET | K38: 未開始
A39: S02 | B39: #3 | C39: 管理網域 | D39: 前置檢查 | E39: S02-03 | F39: 使用全新 Installer（做過 bring-up / converge 的 Installer 會記得舊 domain） | G39: GET https://<installer>/v1/sddcs | H39: 回 [] | I39: CXS Lab 實測 | J39: ENG | K39: 未開始
A40: S02 | B40: #3 | C40: 管理網域 | D40: 執行 | E40: S02-04 | F40: 部署 OVA（可放在 Management Cluster）；admin@local 密碼由密碼保管工具管理，不寫入文件 | G40: vSphere Client > Deploy OVF Template | H40: Powered on | J40: ENG | K40: 未開始
...

Sheet 原計畫對照
A1: 原暫定計畫 13 步 → 建議步驟對照
A2: 判定：照做 / 調整 / 移到最後 / 建議架 / 拆兩段
A3: 原 # | B3: 原步驟 | C3: 判定 | D3: 說明 | E3: 依據 | F3: 建議步驟
A4: 1 | B4: vMotion vRO、vRA to Management Cluster | C4: 調整 | D4: 改為冷遷移；目標 port group 與 vRA 同一 L2 網段（IP / FQDN 不變） | E4: KB 318582；Import Aria Automation 前置 | F4: S01
A5: 2 | B5: Upgrade vRO to 9.1.1 | C5: 移到最後 | D5: external vRO 必須在 vRA → VCFA 之後升；vRO 9.1.1 不支援 vRA 8.18 與 vCenter 8.0U3 | E5: Configure VCF Ops Orchestrator…；Interop Matrix | F5: S15
A6: 3 | B6: Deploy VCF Installer 9.1.1 | C6: 照做 | D6: 全新 Installer、版本 ≥ 9.1.1 | E6: Converge 部署頁 | F6: S02
A7: 4 | B7: Offline Depot??? | C7: 建議架 | D7: 非必要（可 Manual Transfer），但 Installer 內 binaries 不會轉移，後續 VCFA / WLD 升級還要用 | E7: Downloading Binaries to VCF Installer | F7: S03
A8: 5 | B8: Converge Management Cluster to VCF 9.1.1 | C8: 照做 | D8: 先過支援組態檢查；成功後不可逆（PONR） | E8: Supported / Not Supported Configurations | F8: S04
A9: 6 | B9: Import vRA to VCF | C9: 照做 | D9: 前提：vRA 已在管理網域（Step 1） | E9: Import Aria Automation in VCF Ops | F9: S05
A10: 7 | B10: Upgrade vRA to 9.1.1 | C10: 照做 | D10: KB 425489 腳本；5 IP + runtime FQDN 同網段 | E10: Upgrading to VCF Automation 9.1 | F10: S06
A11: 8 | B11: Import 整合雲 | C11: 調整 | D11: import 8.0.3 會自建 3-node NSX 4.2；建議先升 vCenter 再 import、共用管理網域 NSX | E11: Import an Existing vCenter | F11: S09
A12: 9 | B12: Import 中信雲 | C12: 調整 | D12: 同上 | E12: Import an Existing vCenter | F12: S13
A13: 10 | B13: Upgrade 整合雲 to 9.1.1 | C13: 拆兩段 | D13: vCenter 在 import 前以 RDU 升；ESXi 在 import 後走 VCF LCM | E13: Import 頁；WLD 升級頁 | F13: S07 + S10
A14: 11 | B14: SRM 重新註冊（整合雲） | C14: 照做 | D14: 兩站 VAMI Reconfigure + Site Pair Reconnect | E14: KB 446701 | F14: S08
... A16: 13 | B16: SRM 重新註冊（中信雲） | C16: 照做 | D16: 同 11；每次 vCenter 升級後兩站都要做 | E16: KB 446701 | F16: S12

Sheet Gate 簽核
A1: Gate 與 Point of No Return 簽核
A2: PONR = 越過後無官方反向程序；需觀察期與客戶簽核
A3: Gate | B3: 時點 | C3: 內容 | D3: 放行條件 | E3: 簽核角色 | F3: PONR | G3: 結果（Go / No-Go） | H3: 簽核人 | I3: 日期 | J3: 備註
A4: G0 | B4: S00 後 | C4: 盤點與備份 | D4: 阻礙項清零、三套 vCenter 備份可還原、IP/DNS 驗證完成 | E4: PM、ARC | F4: 否
A5: G1 | B5: S04 後 | C5: Converge 完成 | D5: 管理網域 ACTIVE、NSX / VCF Ops 正常、第一次 SFTP 備份成功 | E5: PM、ARC | F5: 是
A6: G2 | B6: S06 後 | C6: VCFA 9.1.1 cutover | D6: Tenant / Provider 登入、資料完整、Day-2 成功；8.18 來源保留至觀察期後 | E6: PM、AUTO | F6: 否
A7: G3 | B7: S09 | C7: 整合雲 import | D7: vCenter 9.1.1 正常、SRM Test Recovery 成功、Compute Manager 已註冊 | E7: PM、ARC、DR | F7: 是
A8: G4 | B8: S13 | C8: 中信雲 import | D8: 同 G3 | E8: PM、ARC、DR | F8: 是
A9: G5 | B9: S16 | C9: vSAN on-disk format | D9: 觀察期無重大事件、客戶簽核 | E9: PM | F9: 是

Sheet IP & DNS 規劃
A1: 新增元件 IP / DNS 規劃
A2: 黃底欄位填實際值；FQDN 全小寫、A / PTR 都要建（KB 453612、KB 440630）
A3: 元件 | B3: IP 數量 | C3: FQDN 需求 | D3: 網段 | E3: 備註 | F3: 實際 FQDN | G3: 實際 IP / 範圍 | H3: VLAN | I3: A / PTR 驗證 | J3: 負責
A4: VCF Installer | B4: 1 | C4: 1 | D4: Mgmt | E4: 可放在 Management Cluster | J4: NET
A5: SDDC Manager | B5: 1 | C5: 1 | D5: Mgmt | J5: NET
A6: NSX Manager（管理網域） | B6: VIP 1 + 節點 1 或 3 | C6: VIP + 每節點 | D6: Mgmt | E6: 無 NSX Edge cluster；NSX 憑證 SAN 含所有節點 FQDN 與 VIP | J6: NET
A7: VCF Operations | B7: 1（Simple）或 3（HA） | C7: 每節點 | D7: Mgmt | E7: 9.1.1 起須在第一個 Instance 的管理網域 | J7: NET
A8: VCF Operations Cloud Proxy | B8: 1 | C8: 1 | D8: Mgmt | J8: NET
A9: License Server | B9: 1 | C9: 1（A + PTR 必要） | D9: Mgmt | E9: KB 440630 | J9: NET
A10: VCF Identity Broker | B10: 1 | C10: 1 | D10: Mgmt | J10: NET
A11: VCF Management Services（services runtime） | B11: IP pool ≥ 12（最多 30） | C11: Fleet / Instance FQDN | D11: Mgmt | E11: 內部網段 198.18.0.0/15 不可與內網重疊（KB 440630） | J11: NET
A12: VCF Automation 9.1.1（升級用） | B12: 5（可不連續或 /29） | C12: runtime FQDN 1（IP 在 pool 外） | D12: vRA 現行網段 | E12: 原 vRA IP 自動轉 VIP、FQDN 沿用 | J12: NET
A13: RDU 暫時 IP — 整合雲 vCenter | B13: 1 | C13: —（不可有既存 PTR） | D13: 整合雲 Mgmt | E13: Switchover 後釋放 | J13: NET
A14: RDU 暫時 IP — 中信雲 vCenter | B14: 1 | C14: —（不可有既存 PTR） | D14: 中信雲 Mgmt | E14: Switchover 後釋放 | J14: NET
A15: Offline Depot Server | B15: 1 | C15: 1 | D15: Mgmt | E15: HTTPS；憑證 SAN 含 FQDN + IP | J15: NET

Sheet 待確認事項
A1: 待確認事項（G0 前關閉）
A3: # | B3: 項目 | C3: 為什麼重要 | D3: 確認方式 | E3: 負責 | F3: 狀態 | G3: 結論 | H3: 日期
A4: 1 | B4: Enhanced Linked Mode | C4: converge 與 import 都不支援 ELM | D4: 客戶確認 | E4: SYS | F4: 已確認 | G4: 三套 vCenter 皆無 ELM | H4: 2026-10-07
A5: 2 | B5: vRA 確切版本 / patch | C5: converge 情境頁要求 8.18.1 P3；import 頁為 8.18.1+ | D5: vracli version | E5: AUTO | F5: 待確認
A6: 3 | B6: vRO 實際版本 | C6: 「8.18.7」查無此 Orchestrator 版號；升級來源需 ≥ 8.18.1 | D6: vracli version | E6: AUTO | F6: 待確認
A7: 4 | B7: vIDM / Aria Suite Lifecycle 位置與版本 | C7: vIDM 升級後仍是 VCFA 驗證來源；是否隨 vRA 一起搬 | D7: vSphere inventory | E7: AUTO | F7: 待確認
A8: 5 | B8: vCenter HA | C8: converge 與 import 都不支援 VCHA（ELM 已於 10/7 確認沒有） | D8: vSphere Client | E8: SYS | F8: 待確認
A9: 6 | B9: 兩朵雲 8.0.3 確切 build | C9: 8.0U3j → 9.1.0 不支援、→ 9.1.1 支援；8.0U3k 需查 Interop（KB 450972 back-in-time） | D9: VAMI / esxcli | E9: SYS | F9: 待確認
A10: 7 | B10: SRM 配對拓樸 | C10: 兩朵雲是否互為配對、PG 方向、replication 方式 → 決定先升哪一站 | D10: SRM UI | E10: DR | F10: 待確認
A11: 8 | B11: WLD import 方案 A / B | C11: A：import 8.0.3（自建 3-node NSX 4.2）／B：先升 vCenter 再 import 共用 NSX（建議） | D11: 設計會議 | E11: ARC、PM | F11: 待確認
A12: 9 | B12: Management Cluster 網段與容量 | C12: 需提供 vRA 同 L2 網段；VCFA 藍綠期間資源約 2 倍 | D12: 網路 / 容量盤點 | E12: NET、ARC | F12: 待確認
A13: 10 | B13: VCF Operations 新部署或沿用 | C13: 9.1.1 起須在第一個 Instance 管理網域；是否已有 Aria Operations 8.18 | D13: 盤點 | E13: ARC | F13: 待確認
A14: 11 | B14: 過渡期 interop | C14: Interop 對 Aria Automation 8.18 ↔ vCenter / ESX 9.x 標 Not Supported（推定指 endpoint）；過渡期盡量縮短、必要時開 SR 確認 | D14: Interop Matrix / SR | E14: ARC | F14: 待確認
A15: 12 | B15: vLCM image 叢集 Shift+R 退版 | C15: KB 316592 未說明對 vLCM image 一致性的影響 | D15: Lab 驗證 + SR | E15: ENG | F15: 待確認

Sheet 官方文件
A1: 官方依據：Broadcom TechDocs 與 KB
A3: 類別 | B3: 文件 | C3: URL
A4: Converge | B4: Supported and Not Supported Configurations to Converge to VCF | C4: https://techdocs.broadcom.com/us/en/vmware-cis/vcf/vcf-9-0-and-later/9-1/deployment/converging-your-existing-vsphere-infrastructure-to-a-vcf-or-vvf-platform-/supported-and-not-supported-configurations.html
A5: Converge | B5: Deploy Components by Using VCF Installer to Complete the Converging to VCF Process | C5: https://techdocs.broadcom.com/us/en/vmware-cis/vcf/vcf-9-0-and-later/9-1/deployment/converging-your-existing-vsphere-infrastructure-to-a-vcf-or-vvf-platform-/use-existing-vsphere-infrastructure-to-create-a-new-vcf-fleet-or-a-new-vcf-instance-using-the-deployment-wizard.html
A6: Converge | B6: Converge vCenter, ESX Hosts, Aria Suite Lifecycle and Aria Automation | C6: https://techdocs.broadcom.com/us/en/vmware-cis/vcf/vcf-9-0-and-later/9-1/deployment/converging-your-existing-vsphere-infrastructure-to-a-vcf-or-vvf-platform-/supported-scenarios-to-converge-to-vcf/converge-your-existing-vcenter-instance-esx-hosts-vrealize-suite-lifecycle-manager-and-vmware-aria-automation.html
A7: Depot | B7: Downloading Binaries to VCF Installer | C7: https://techdocs.broadcom.com/us/en/vmware-cis/vcf/vcf-9-0-and-later/9-1/deployment/deploying-a-new-vmware-cloud-foundation-or-vmware-vsphere-foundation-private-cloud-/preparing-your-environment/downloading-binaries-to-the-vcf-installer-appliance.html
A8: Depot | B8: Connect VCF Installer to Broadcom or an Offline Depot | C8: https://techdocs.broadcom.com/us/en/vmware-cis/vcf/vcf-9-0-and-later/9-1/deployment/deploying-a-new-vmware-cloud-foundation-or-vmware-vsphere-foundation-private-cloud-/preparing-your-environment/downloading-binaries-to-the-vcf-installer-appliance/connect-to-an-online-depot-to-download-binaries.html
A9: Depot | B9: Connect SDDC Manager to a Software Depot | C9: https://techdocs.broadcom.com/us/en/vmware-cis/vcf/vcf-9-0-and-later/9-1/lifecycle-management/binary-management-for-vmware-cloud-foundation/connect-sddc-manager-to-a-software-depot-for-downloading-bundles.html
A10: Automation | B10: Import an Existing VMware Aria Automation Instance in VCF Operations | C10: https://techdocs.broadcom.com/us/en/vmware-cis/vcf/vcf-9-0-and-later/9-1/deployment/upgrading-cloud-foundation/phase-3-import-and-upgrade-aria-automation-8-to-vcf-automation-9/import-an-existing-vmware-aria-automation-instance-in-vcf-operations.html
A11: Automation | B11: Upgrading to VCF Automation 9.1 | C11: https://techdocs.broadcom.com/us/en/vmware-cis/vcf/vcf-9-0-and-later/9-1/deployment/upgrading-cloud-foundation/phase-3-import-and-upgrade-aria-automation-8-to-vcf-automation-9.html
A12: Automation | B12: Perform the Upgrade to VCF Automation 9.1 | C12: https://techdocs.broadcom.com/us/en/vmware-cis/vcf/vcf-9-0-and-later/9-1/deployment/upgrading-cloud-foundation/phase-3-import-and-upgrade-aria-automation-8-to-vcf-automation-9/upgrade-to-vcf-automation.html
A13: Automation | B13: Migrate VCF Automation SSO from vIDM to VCF Identity Broker | C13: https://techdocs.broadcom.com/us/en/vmware-cis/vcf/vcf-9-0-and-later/9-1/deployment/upgrading-cloud-foundation/phase-3-import-and-upgrade-aria-automation-8-to-vcf-automation-9/migrate-vcf-automation-single-sign-on-configuration-from-vmware-identity-manager-to-vcf-identity-broker.html
A14: Orchestrator | B14: Upgrade to VCF Operations Orchestrator 9.1 | C14: https://techdocs.broadcom.com/us/en/vmware-cis/vcf/vcf-9-0-and-later/9-1/deployment/upgrading-cloud-foundation/upgrade-a-standalone-or-clustered-vrealize-orchestrator-8-0-1-deployment-with-iso-image.html
... A46: KB 316592 | B46: ESXi Shift+R 回復前一版（altbootbank） | C46: https://knowledge.broadcom.com/external/article/316592

Sheet Lab 驗證覆蓋
A1: CXS Lab 驗證覆蓋（github.com/kostenyang）
A2: 未驗證的步驟正式變更前須於 Lab 補測
A3: 步驟 | B3: 內容 | C3: 狀態 | D3: 實測日期 | E3: 結果 | F3: 差異 / 缺口 | G3: Git 出處
A4: S01 | B4: vRA 冷遷移進管理網域 | C4: 已驗證 | D4: 2026-09-09（m02） | E4: 熱遷移因 CPU feature 失敗 → 冷遷移 165 GB 約 97 分；搬入後 import precheck 通過 | F4: Lab 是管理網域已建好後才搬；先搬再 Converge 未驗證 | G4: vra-lifecycle worklog Phase ④
A5: S02 / S03 | B5: VCF Installer、Offline Depot | C5: 已驗證 | D5: 多次（9 月） | E5: v5 depot 腳本、CA 匯入、客戶交付包；depot URL 用 IP | F5: — | G5: vcf9offlinescript、vcf-download-tool
A6: S04 | B6: Converge vCenter 9.1.1 + ESXi 9.1.1 | C6: 已驗證 | D6: 2026-09-19 / 09-30 / 10-05 | E6: 多 cluster、無 overlay、overlay over mgmt、沿用既有 VCF Ops 皆 COMPLETED_WITH_SUCCESS；約 5–5.5 h | F6: Lab 是 nested 4 台；CTBC 為 6 台實體 | G6: v8tov9 converge/、converge-existing-ops/
A7: S05 | B7: Import vRA 8.18.1 | C7: 已驗證 | D7: 2026-09-06 / 10-07（m03） | E7: import 約 5 分，來源不受影響 | F7: — | G7: vra-lifecycle（branch vra8-import-upgrade-m03）
A8: S06 | B8: vRA → VCF Automation 9.1.1 | C8: 已驗證 | D8: 2026-10-07（m03） | E8: precheck 一次過 36 分、升級 4 h 47 m 一次成功、中斷約 44 分、資料 ID 全相同；來源自動 snapshot | F8: 9/9 m02（fleet 9.1.0.0400）曾 7 h 55 m + 假失敗 | G8: vra-lifecycle（branch vra8-import-upgrade-m03）
A9: S07 / S11 | B9: vCenter 8.0.3 → 9.1.1 | C9: 已驗證 | D9: 2026-08-19 / 09-21 / 10-02 | E9: RDU 33 分；CLI migration 50 分；RDU 遇 NSX < 9.1 註冊會卡 switchover | F9: Lab 無 SRM extension | G9: v8tov9 vc-8.0.3-to-9.1.1-firstboot-failure、customer-vvf-no-sddcm.md、import-wld/cli
A10: S08 / S12 | B10: SRM Reconfigure + Reconnect | C10: 未驗證 | D10: — | E10: — | F10: Git 無 SRM 實測 → 依 KB 446701；建議 Lab 補測 | G10: —
A11: S09 / S13 | B11: Import WLD 共用管理網域 NSX | C11: 已驗證 | D11: 2026-10-03 | E11: vCenter 9.1.1 + ESXi 8.0.3 匯入 57/57、約 15 分；precheck 3 個 Error 已有修法 | F11: — | G11: v8tov9 import-wld/
A12: S10 / S14 | B12: 匯入後 ESXi 8.0.3 → 9.1.1（VCF LCM） | C12: 未驗證 | D12: — | E12: 相關：vLCM 升獨立主機（9/29）、ESX depot zip 取得法 | F12: Lab 匯入後主機維持 8.0.3，未在 VCF 內升級 → 建議 Lab 補測 | G12: v8tov9 esxi-standalone-upgrade/
A13: S15 | B13: vRO → 9.1.1 | C13: 未驗證 | D13: — | E13: — | F13: Git 無 vRO standalone 升級實測 → 依 TechDocs；建議 Lab 補測 | G13: —
A14: 方案 A | B14: Import 8.0.3 並自建 NSX 4.2 | C14: 未驗證 | D14: — | E14: — | F14: Lab 未測 → 也是建議方案 B 的理由之一 | G14: —

Sheet Git 參考文件
A1: Git 參考文件（github.com/kostenyang）— 內部參考
A2: CXS Lab 實測紀錄，非官方文件；private repo 內含 lab 資訊，交付客戶前可刪除本頁
A3: 對應步驟 | B3: Repo | C3: 路徑 | D3: 可參考的內容
A4: S01 | B4: vra-lifecycle（private） | C4: runbooks/vcf911-vra8-import-upgrade-worklog.md › Phase ④ | D4: vRA appliance 跨 vCenter 搬進管理網域：熱遷移因 CPU feature 失敗、165 GB 冷遷移約 97 分；/vco/api/healthstatus 作為就緒判斷
A5: S01 | B5: vra-lifecycle（private） | C5: runbooks/scripts/vcf911-vra8-upgrade/coldmove-vra9.ps1、xvmotion-vra9.ps1 | D5: PowerCLI 冷 / 熱遷移腳本（PowerCLI 模組需釘同一版 13.5）
A6: S01 | B6: vra-lifecycle（private） | C6: runbooks/vra8-cross-vcenter-migration-day2-power.md | D6: vRA 管的 workload VM 跨 vCenter 搬遷後 Day-2 可用；_ovfenv ISO 擋熱 vMotion → 冷搬（對象是 workload VM，不是 appliance）
A7: S02 / S04 | B7: vcf9.1-lab-private（private） | C7: installer-deploy/（Invoke-Vcf9InstallerDeploy_v1.ps1、spec/management-domain.template_v1.json） | D7: Installer 部署腳本與 spec 範本
A8: S03 | B8: vcf9offlinescript | C8: README.md、CUSTOMER-DEPLOY-GUIDE.md、create_vcf9_depot_server_v5.sh、import_vcf9depot_ca.sh | D8: Offline depot 一鍵建置（nginx / apache、HTTPS、basic auth）、CA 匯入 Installer / SDDC Manager / VCF Ops、客戶交付指南
A9: S03 | B9: vcf9offlinescript | C9: INSTALLER_CONNECT_TROUBLESHOOTING.md、DEPOT-WAY-A/B/C、DOWNLOAD-INTO-DEPOT.md | D9: Installer 連 depot 除錯；三種灌 binaries 的方式
A10: S03 | B10: vcf-download-tool | C10: README / CLI-REFERENCE / GOTCHAS / PROXY / WINDOWS | D10: VCF Download Tool 用法、proxy、Windows、activation code 判讀
A11: S03 | B11: vcf9.1-lab-private（private）/ vcf9offlinescript | C11: FLEET-DEPOT-CA-TRUST.md | D11: Fleet Depot Service 信任自簽 depot CA（KB 442978；private 版含腳本）
A12: S04 | B12: v8tov9 | C12: converge/README.md（範本 1–3） | D12: Converge 9.1.1 JSON 範本：不給 TEP / 沿用既有 NSX / 多 cluster；逐 cluster 驗證項；evacuate_offline_vms；vSS 是硬擋點
A13: S04 | B13: v8tov9 | C13: converge/no-overlay/（README + VCF911-Converge-NoOverlay.docx） | D13: 完全不部署 overlay 的 converge：23 頁手冊、5 個里程碑耗時、14 個踩坑速查
A14: S04 | B14: v8tov9 | C14: converge-existing-ops/README.md | D14: 沿用既有 VCF Ops / License Server；Plan › Existing Component；容量驗證只看叢集總量；depot URL 用 IP
... A30: 全程 | B30: lab-info | C30: runbooks/backup-sftp.md、runbooks/depot-server.md | D30: SFTP 備份、depot server 紀錄
